
Not Found: /favicon.ico
[29/Jun/2021 16:33:34] "GET /favicon.ico HTTP/1.1" 404 2083
Not Found: /
[29/Jun/2021 16:33:37] "GET / HTTP/1.1" 404 2032
Not Found: /favicon.ico
[29/Jun/2021 16:33:37] "GET /favicon.ico HTTP/1.1" 404 2083
Not Found: /favicon.ico
[29/Jun/2021 16:33:37] "GET /favicon.ico HTTP/1.1" 404 2083
Not Found: /favicon.ico
[29/Jun/2021 16:33:37] "GET /favicon.ico HTTP/1.1" 404 2083
Not Found: /favicon.ico
[29/Jun/2021 16:33:41] "GET /favicon.ico HTTP/1.1" 404 2083
Not Found: /favicon.ico
[29/Jun/2021 16:33:43] "GET /favicon.ico HTTP/1.1" 404 2083
Not Found: /favicon.ico
[29/Jun/2021 16:33:43] "GET /favicon.ico HTTP/1.1" 404 2083
Not Found: /favicon.ico
[29/Jun/2021 16:33:44] "GET /favicon.ico HTTP/1.1" 404 2083
Not Found: /favicon.ico
[29/Jun/2021 16:33:44] "GET /favicon.ico HTTP/1.1" 404 2083
Not Found: /favicon.ico
[29/Jun/2021 16:33:44] "GET /favicon.ico HTTP/1.1" 404 2083
[29/Jun/2021 16:33:45] "GET /polls/ HTTP/1.1" 200 21
Not Found: /favicon.ico
[29/Jun/2021 16:33:45] "GET /favicon.ico HTTP/1.1" 404 2083
Not Found: /favicon.ico
[29/Jun/2021 16:33:45] "GET /favicon.ico HTTP/1.1" 404 2083
Not Found: /polls/favicon.ico
[29/Jun/2021 16:33:45] "GET /polls/favicon.ico HTTP/1.1" 404 2162
Not Found: /favicon.ico
[29/Jun/2021 16:33:46] "GET /favicon.ico HTTP/1.1" 404 2083
Not Found: /favicon.ico
[29/Jun/2021 16:33:46] "GET /favicon.ico HTTP/1.1" 404 2083
Performing system checks...

System check identified no issues (0 silenced).

You have 15 unapplied migration(s). Your project may not work properly until you apply the migrations for app(s): admin, auth, contenttypes, sessions.
Run 'python manage.py migrate' to apply them.
June 29, 2021 - 16:32:37
Django version 2.1.8, using settings 'mysite.settings'
Starting development server at http://0.0.0.0:8000/
Quit the server with CONTROL-C.
Exception ignored in thread started by: <function check_errors.<locals>.wrapper at 0x7fa173385160>
Traceback (most recent call last):
  File "/home/python/python3/lib/python3.8/site-packages/django/utils/autoreload.py", line 225, in wrapper
    fn(*args, **kwargs)
  File "/home/python/python3/lib/python3.8/site-packages/django/core/management/commands/runserver.py", line 109, in inner_run
    autoreload.raise_last_exception()
  File "/home/python/python3/lib/python3.8/site-packages/django/utils/autoreload.py", line 248, in raise_last_exception
    raise _exception[1]
  File "/home/python/python3/lib/python3.8/site-packages/django/core/management/__init__.py", line 337, in execute
    autoreload.check_errors(django.setup)()
  File "/home/python/python3/lib/python3.8/site-packages/django/utils/autoreload.py", line 225, in wrapper
    fn(*args, **kwargs)
  File "/home/python/python3/lib/python3.8/site-packages/django/__init__.py", line 24, in setup
    apps.populate(settings.INSTALLED_APPS)
  File "/home/python/python3/lib/python3.8/site-packages/django/apps/registry.py", line 112, in populate
    app_config.import_models()
  File "/home/python/python3/lib/python3.8/site-packages/django/apps/config.py", line 198, in import_models
    self.models_module = import_module(models_module_name)
  File "/home/python/python3/lib/python3.8/importlib/__init__.py", line 127, in import_module
    return _bootstrap._gcd_import(name[level:], package, level)
  File "<frozen importlib._bootstrap>", line 1014, in _gcd_import
  File "<frozen importlib._bootstrap>", line 991, in _find_and_load
  File "<frozen importlib._bootstrap>", line 975, in _find_and_load_unlocked
  File "<frozen importlib._bootstrap>", line 671, in _load_unlocked
  File "<frozen importlib._bootstrap_external>", line 783, in exec_module
  File "<frozen importlib._bootstrap>", line 219, in _call_with_frames_removed
  File "/home/python/Django/mysite/polls/models.py", line 5, in <module>
    class Question(models.Model):
  File "/home/python/Django/mysite/polls/models.py", line 6, in Question
    question_text = models.charFeild(max_length=200)
AttributeError: module 'django.db.models' has no attribute 'charFeild'
Exception ignored in thread started by: <function check_errors.<locals>.wrapper at 0x7f8a1ef1b160>
Traceback (most recent call last):
  File "/home/python/python3/lib/python3.8/site-packages/django/utils/autoreload.py", line 225, in wrapper
    fn(*args, **kwargs)
  File "/home/python/python3/lib/python3.8/site-packages/django/core/management/commands/runserver.py", line 109, in inner_run
    autoreload.raise_last_exception()
  File "/home/python/python3/lib/python3.8/site-packages/django/utils/autoreload.py", line 248, in raise_last_exception
    raise _exception[1]
  File "/home/python/python3/lib/python3.8/site-packages/django/core/management/__init__.py", line 337, in execute
    autoreload.check_errors(django.setup)()
  File "/home/python/python3/lib/python3.8/site-packages/django/utils/autoreload.py", line 225, in wrapper
    fn(*args, **kwargs)
  File "/home/python/python3/lib/python3.8/site-packages/django/__init__.py", line 24, in setup
    apps.populate(settings.INSTALLED_APPS)
  File "/home/python/python3/lib/python3.8/site-packages/django/apps/registry.py", line 112, in populate
    app_config.import_models()
  File "/home/python/python3/lib/python3.8/site-packages/django/apps/config.py", line 198, in import_models
    self.models_module = import_module(models_module_name)
  File "/home/python/python3/lib/python3.8/importlib/__init__.py", line 127, in import_module
    return _bootstrap._gcd_import(name[level:], package, level)
  File "<frozen importlib._bootstrap>", line 1014, in _gcd_import
  File "<frozen importlib._bootstrap>", line 991, in _find_and_load
  File "<frozen importlib._bootstrap>", line 975, in _find_and_load_unlocked
  File "<frozen importlib._bootstrap>", line 671, in _load_unlocked
  File "<frozen importlib._bootstrap_external>", line 783, in exec_module
  File "<frozen importlib._bootstrap>", line 219, in _call_with_frames_removed
  File "/home/python/Django/mysite/polls/models.py", line 5, in <module>
    class Question(models.Model):
  File "/home/python/Django/mysite/polls/models.py", line 6, in Question
    question_text = models.charFeild(max_length=200)
AttributeError: module 'django.db.models' has no attribute 'charFeild'
Exception ignored in thread started by: <function check_errors.<locals>.wrapper at 0x7ff456e53160>
Traceback (most recent call last):
  File "/home/python/python3/lib/python3.8/site-packages/django/utils/autoreload.py", line 225, in wrapper
    fn(*args, **kwargs)
  File "/home/python/python3/lib/python3.8/site-packages/django/core/management/commands/runserver.py", line 109, in inner_run
    autoreload.raise_last_exception()
  File "/home/python/python3/lib/python3.8/site-packages/django/utils/autoreload.py", line 248, in raise_last_exception
    raise _exception[1]
  File "/home/python/python3/lib/python3.8/site-packages/django/core/management/__init__.py", line 337, in execute
    autoreload.check_errors(django.setup)()
  File "/home/python/python3/lib/python3.8/site-packages/django/utils/autoreload.py", line 225, in wrapper
    fn(*args, **kwargs)
  File "/home/python/python3/lib/python3.8/site-packages/django/__init__.py", line 24, in setup
    apps.populate(settings.INSTALLED_APPS)
  File "/home/python/python3/lib/python3.8/site-packages/django/apps/registry.py", line 112, in populate
    app_config.import_models()
  File "/home/python/python3/lib/python3.8/site-packages/django/apps/config.py", line 198, in import_models
    self.models_module = import_module(models_module_name)
  File "/home/python/python3/lib/python3.8/importlib/__init__.py", line 127, in import_module
    return _bootstrap._gcd_import(name[level:], package, level)
  File "<frozen importlib._bootstrap>", line 1014, in _gcd_import
  File "<frozen importlib._bootstrap>", line 991, in _find_and_load
  File "<frozen importlib._bootstrap>", line 975, in _find_and_load_unlocked
  File "<frozen importlib._bootstrap>", line 671, in _load_unlocked
  File "<frozen importlib._bootstrap_external>", line 783, in exec_module
  File "<frozen importlib._bootstrap>", line 219, in _call_with_frames_removed
  File "/home/python/Django/mysite/polls/models.py", line 5, in <module>
    class Question(models.Model):
  File "/home/python/Django/mysite/polls/models.py", line 6, in Question
    question_text = models.charField(max_length=200)
AttributeError: module 'django.db.models' has no attribute 'charField'
Exception ignored in thread started by: <function check_errors.<locals>.wrapper at 0x7f77af4f5550>
Traceback (most recent call last):
  File "/home/python/python3/lib/python3.8/site-packages/django/utils/autoreload.py", line 225, in wrapper
    fn(*args, **kwargs)
  File "/home/python/python3/lib/python3.8/site-packages/django/core/management/commands/runserver.py", line 109, in inner_run
    autoreload.raise_last_exception()
  File "/home/python/python3/lib/python3.8/site-packages/django/utils/autoreload.py", line 248, in raise_last_exception
    raise _exception[1]
  File "/home/python/python3/lib/python3.8/site-packages/django/core/management/__init__.py", line 337, in execute
    autoreload.check_errors(django.setup)()
  File "/home/python/python3/lib/python3.8/site-packages/django/utils/autoreload.py", line 225, in wrapper
    fn(*args, **kwargs)
  File "/home/python/python3/lib/python3.8/site-packages/django/__init__.py", line 24, in setup
    apps.populate(settings.INSTALLED_APPS)
  File "/home/python/python3/lib/python3.8/site-packages/django/apps/registry.py", line 112, in populate
    app_config.import_models()
  File "/home/python/python3/lib/python3.8/site-packages/django/apps/config.py", line 198, in import_models
    self.models_module = import_module(models_module_name)
  File "/home/python/python3/lib/python3.8/importlib/__init__.py", line 127, in import_module
    return _bootstrap._gcd_import(name[level:], package, level)
  File "<frozen importlib._bootstrap>", line 1014, in _gcd_import
  File "<frozen importlib._bootstrap>", line 991, in _find_and_load
  File "<frozen importlib._bootstrap>", line 975, in _find_and_load_unlocked
  File "<frozen importlib._bootstrap>", line 671, in _load_unlocked
  File "<frozen importlib._bootstrap_external>", line 783, in exec_module
  File "<frozen importlib._bootstrap>", line 219, in _call_with_frames_removed
  File "/home/python/Django/mysite/polls/models.py", line 9, in <module>
    class Choice(models.Model):
  File "/home/python/Django/mysite/polls/models.py", line 10, in Choice
    question = model.ForeignKey(Question, on_delete=models.CASCADE)
NameError: name 'model' is not defined
Not Found: /favicon.ico
[29/Jun/2021 16:47:41] "GET /favicon.ico HTTP/1.1" 404 2083
Not Found: /favicon.ico
[29/Jun/2021 16:47:43] "GET /favicon.ico HTTP/1.1" 404 2083
Not Found: /favicon.ico
[29/Jun/2021 16:47:43] "GET /favicon.ico HTTP/1.1" 404 2083
Not Found: /favicon.ico
[29/Jun/2021 16:47:46] "GET /favicon.ico HTTP/1.1" 404 2083
Not Found: /favicon.ico
[29/Jun/2021 16:47:46] "GET /favicon.ico HTTP/1.1" 404 2083
Not Found: /favicon.ico
[29/Jun/2021 16:47:47] "GET /favicon.ico HTTP/1.1" 404 2083
Not Found: /favicon.ico
[29/Jun/2021 16:49:29] "GET /favicon.ico HTTP/1.1" 404 2083
[29/Jun/2021 17:00:00] code 400, message Bad HTTP/0.9 request type ('Z¥\x01')
[29/Jun/2021 17:00:00] "Z¥     " 400 -
[29/Jun/2021 17:32:38] code 400, message Bad HTTP/0.9 request type ('\x16\x03\x01\x00u\x01\x00\x00q\x03\x03Õ\x0fÇ^ÝÚ\x9bâ]ß¢CÆÚµ¦`4%\x81×£\x9eøPãé\x8e¶)\x89\x93\x00\x00\x1aÀ/À+À\x11À\x07À\x13À')
[29/Jun/2021 17:32:38] You're accessing the development server over HTTPS, but it only supports HTTP.

[29/Jun/2021 18:12:16] code 400, message Bad HTTP/0.9 request type ('Z¥\x01')
[29/Jun/2021 18:12:16] "Z¥     " 400 -
[29/Jun/2021 18:54:05] code 400, message Bad HTTP/0.9 request type ('\x03\x00\x00/*à\x00\x00\x00\x00\x00Cookie:')
[29/Jun/2021 18:54:05] "  /*à     Cookie: mstshash=Administr" 400 -
[29/Jun/2021 19:59:10] code 400, message Bad HTTP/0.9 request type ('Z¥\x01')
[29/Jun/2021 19:59:10] "Z¥     " 400 -
Not Found: /_ignition/execute-solution
[29/Jun/2021 21:00:44] "POST /_ignition/execute-solution HTTP/1.1" 404 2129
[29/Jun/2021 21:41:35] code 400, message Bad HTTP/0.9 request type ('Z¥\x01')
[29/Jun/2021 21:41:35] "Z¥     " 400 -
----------------------------------------
Exception happened during processing of request from ('104.152.52.9', 33035)
Traceback (most recent call last):
  File "/home/python/python3/lib/python3.8/socketserver.py", line 650, in process_request_thread
    self.finish_request(request, client_address)
  File "/home/python/python3/lib/python3.8/socketserver.py", line 360, in finish_request
    self.RequestHandlerClass(request, client_address, self)
  File "/home/python/python3/lib/python3.8/socketserver.py", line 720, in __init__
    self.handle()
  File "/home/python/python3/lib/python3.8/site-packages/django/core/servers/basehttp.py", line 169, in handle
    self.handle_one_request()
  File "/home/python/python3/lib/python3.8/site-packages/django/core/servers/basehttp.py", line 179, in handle_one_request
    self.raw_requestline = self.rfile.readline(65537)
  File "/home/python/python3/lib/python3.8/socket.py", line 669, in readinto
    return self._sock.recv_into(b)
ConnectionResetError: [Errno 104] Connection reset by peer
----------------------------------------
Invalid HTTP_HOST header: 'allen_cvm:8000'. The domain name provided is not valid according to RFC 1034/1035.
Bad Request: /
[29/Jun/2021 21:45:18] code 400, message Bad HTTP/0.9 request type ('l\x00')
[29/Jun/2021 21:45:18] "l          " 400 -
Invalid HTTP_HOST header: 'allen_cvm:8000'. The domain name provided is not valid according to RFC 1034/1035.
Bad Request: /nice ports,/Trinity.txt.bak
[29/Jun/2021 21:45:19] code 400, message Bad request syntax ('\x05\x04\x00\x01\x02\x80\x05\x01\x00\x03')
[29/Jun/2021 21:45:19] "  " 400 -
[29/Jun/2021 21:45:25] code 400, message Bad request syntax ('\x04\x01\x00\x16\x7f\x00\x00\x01root\x00')
[29/Jun/2021 21:45:25] "   root " 400 -
Invalid HTTP_HOST header: 'allen_cvm:8000'. The domain name provided is not valid according to RFC 1034/1035.
Bad Request: /
[29/Jun/2021 21:45:25] code 400, message Bad request version ('RTSP/1.0')
[29/Jun/2021 21:45:25] "OPTIONS / RTSP/1.0" 400 -
[29/Jun/2021 21:45:31] code 400, message Bad request version ('\x00\x01\x97|\x00\x00\x00\x00\x00\x00\x00\x00\x00\x00\x00\x00\x00\x00\x00\x00\x00\x00\x00\x00')
[29/Jun/2021 21:45:31] "  (rþ          |                    " 400 -
[29/Jun/2021 21:45:36] code 400, message Bad HTTP/0.9 request type ('\x00')
[29/Jun/2021 21:45:36] "          versionbind   " 400 -
[29/Jun/2021 21:45:41] code 400, message Bad HTTP/0.9 request type ('\x00')
[29/Jun/2021 21:45:41] "            " 400 -
[29/Jun/2021 21:45:41] code 400, message Bad request syntax ('HELP')
[29/Jun/2021 21:45:41] "HELP" 400 -
[29/Jun/2021 21:45:42] code 400, message Bad request syntax ('\x16\x03\x00\x00S\x01\x00\x00O\x03\x00?G×÷º,îê²`~ó\x00ý\x82{¹Õ\x96Èw\x9bæÄÛ<=Ûoï\x10n\x00\x00(\x00\x16\x00\x13\x00')
[29/Jun/2021 21:45:42] You're accessing the development server over HTTPS, but it only supports HTTP.

[29/Jun/2021 21:45:47] code 400, message Bad request version ('0.12\x00')
[29/Jun/2021 21:45:47] "   ¤ÿSMBr    @              @     PC NETWORK PROGRAM 1.0 MICROSOFT NETWORKS 1.03 MICROSOFT NETWORKS 3.0 LANMAN1.0 LM1.2X002 Samba NT LANMAN 1.0 NT LM 0.12 " 400 -
[29/Jun/2021 21:45:47] code 400, message Bad request syntax ('\x01default')
[29/Jun/2021 21:45:47] "default" 400 -
[29/Jun/2021 21:45:52] code 400, message Bad HTTP/0.9 request type ('0')
[29/Jun/2021 21:45:53] "0`  " 400 -
----------------------------------------
Exception happened during processing of request from ('104.152.52.74', 48669)
Traceback (most recent call last):
  File "/home/python/python3/lib/python3.8/socketserver.py", line 650, in process_request_thread
    self.finish_request(request, client_address)
  File "/home/python/python3/lib/python3.8/socketserver.py", line 360, in finish_request
    self.RequestHandlerClass(request, client_address, self)
  File "/home/python/python3/lib/python3.8/socketserver.py", line 720, in __init__
    self.handle()
  File "/home/python/python3/lib/python3.8/site-packages/django/core/servers/basehttp.py", line 169, in handle
    self.handle_one_request()
  File "/home/python/python3/lib/python3.8/site-packages/django/core/servers/basehttp.py", line 179, in handle_one_request
    self.raw_requestline = self.rfile.readline(65537)
  File "/home/python/python3/lib/python3.8/socket.py", line 669, in readinto
    return self._sock.recv_into(b)
ConnectionResetError: [Errno 104] Connection reset by peer
----------------------------------------
Invalid HTTP_HOST header: 'allen_cvm:8000'. The domain name provided is not valid according to RFC 1034/1035.
Bad Request: /
[29/Jun/2021 23:04:12] code 400, message Bad HTTP/0.9 request type ('l\x00')
[29/Jun/2021 23:04:12] "l          " 400 -
Invalid HTTP_HOST header: 'allen_cvm:8000'. The domain name provided is not valid according to RFC 1034/1035.
Bad Request: /nice ports,/Trinity.txt.bak
[29/Jun/2021 23:04:13] code 400, message Bad request syntax ('\x05\x04\x00\x01\x02\x80\x05\x01\x00\x03')
[29/Jun/2021 23:04:13] "  " 400 -
[29/Jun/2021 23:04:18] code 400, message Bad request syntax ('\x04\x01\x00\x16\x7f\x00\x00\x01root\x00')
[29/Jun/2021 23:04:18] "   root " 400 -
Invalid HTTP_HOST header: 'allen_cvm:8000'. The domain name provided is not valid according to RFC 1034/1035.
Bad Request: /
[29/Jun/2021 23:04:19] code 400, message Bad request version ('RTSP/1.0')
[29/Jun/2021 23:04:19] "OPTIONS / RTSP/1.0" 400 -
[29/Jun/2021 23:04:24] code 400, message Bad request version ('\x00\x01\x97|\x00\x00\x00\x00\x00\x00\x00\x00\x00\x00\x00\x00\x00\x00\x00\x00\x00\x00\x00\x00')
[29/Jun/2021 23:04:24] "  (rþ          |                    " 400 -
[29/Jun/2021 23:04:29] code 400, message Bad HTTP/0.9 request type ('\x00')
[29/Jun/2021 23:04:29] "          versionbind   " 400 -
[29/Jun/2021 23:04:35] code 400, message Bad HTTP/0.9 request type ('\x00')
[29/Jun/2021 23:04:35] "            " 400 -
[29/Jun/2021 23:04:35] code 400, message Bad request syntax ('HELP')
[29/Jun/2021 23:04:35] "HELP" 400 -
[29/Jun/2021 23:04:35] code 400, message Bad request syntax ('\x16\x03\x00\x00S\x01\x00\x00O\x03\x00?G×÷º,îê²`~ó\x00ý\x82{¹Õ\x96Èw\x9bæÄÛ<=Ûoï\x10n\x00\x00(\x00\x16\x00\x13\x00')
[29/Jun/2021 23:04:35] You're accessing the development server over HTTPS, but it only supports HTTP.

[29/Jun/2021 23:04:41] code 400, message Bad request version ('0.12\x00')
[29/Jun/2021 23:04:41] "   ¤ÿSMBr    @              @     PC NETWORK PROGRAM 1.0 MICROSOFT NETWORKS 1.03 MICROSOFT NETWORKS 3.0 LANMAN1.0 LM1.2X002 Samba NT LANMAN 1.0 NT LM 0.12 " 400 -
[29/Jun/2021 23:05:36] code 400, message Bad HTTP/0.9 request type ('Z¥\x01')
[29/Jun/2021 23:05:36] "Z¥     " 400 -
Not Found: /
[29/Jun/2021 23:13:51] "GET / HTTP/1.1" 404 2032
----------------------------------------
Exception happened during processing of request from ('104.152.52.63', 55035)
Traceback (most recent call last):
  File "/home/python/python3/lib/python3.8/socketserver.py", line 650, in process_request_thread
    self.finish_request(request, client_address)
  File "/home/python/python3/lib/python3.8/socketserver.py", line 360, in finish_request
    self.RequestHandlerClass(request, client_address, self)
  File "/home/python/python3/lib/python3.8/socketserver.py", line 720, in __init__
    self.handle()
  File "/home/python/python3/lib/python3.8/site-packages/django/core/servers/basehttp.py", line 169, in handle
    self.handle_one_request()
  File "/home/python/python3/lib/python3.8/site-packages/django/core/servers/basehttp.py", line 179, in handle_one_request
    self.raw_requestline = self.rfile.readline(65537)
  File "/home/python/python3/lib/python3.8/socket.py", line 669, in readinto
    return self._sock.recv_into(b)
ConnectionResetError: [Errno 104] Connection reset by peer
----------------------------------------
Invalid HTTP_HOST header: 'allen_cvm:8000'. The domain name provided is not valid according to RFC 1034/1035.
Bad Request: /
[29/Jun/2021 23:59:38] code 400, message Bad HTTP/0.9 request type ('l\x00')
[29/Jun/2021 23:59:38] "l          " 400 -
Invalid HTTP_HOST header: 'allen_cvm:8000'. The domain name provided is not valid according to RFC 1034/1035.
Bad Request: /nice ports,/Trinity.txt.bak
[29/Jun/2021 23:59:39] code 400, message Bad request syntax ('\x05\x04\x00\x01\x02\x80\x05\x01\x00\x03')
[29/Jun/2021 23:59:39] "  " 400 -
[29/Jun/2021 23:59:45] code 400, message Bad request syntax ('\x04\x01\x00\x16\x7f\x00\x00\x01root\x00')
[29/Jun/2021 23:59:45] "   root " 400 -
Invalid HTTP_HOST header: 'allen_cvm:8000'. The domain name provided is not valid according to RFC 1034/1035.
Bad Request: /
[29/Jun/2021 23:59:45] code 400, message Bad request version ('RTSP/1.0')
[29/Jun/2021 23:59:45] "OPTIONS / RTSP/1.0" 400 -
[29/Jun/2021 23:59:51] code 400, message Bad request version ('\x00\x01\x97|\x00\x00\x00\x00\x00\x00\x00\x00\x00\x00\x00\x00\x00\x00\x00\x00\x00\x00\x00\x00')
[29/Jun/2021 23:59:51] "  (rþ          |                    " 400 -
[29/Jun/2021 23:59:56] code 400, message Bad HTTP/0.9 request type ('\x00')
[29/Jun/2021 23:59:56] "          versionbind   " 400 -
[30/Jun/2021 00:00:01] code 400, message Bad HTTP/0.9 request type ('\x00')
[30/Jun/2021 00:00:01] "            " 400 -
[30/Jun/2021 00:00:01] code 400, message Bad request syntax ('HELP')
[30/Jun/2021 00:00:01] "HELP" 400 -
[30/Jun/2021 00:00:02] code 400, message Bad request syntax ('\x16\x03\x00\x00S\x01\x00\x00O\x03\x00?G×÷º,îê²`~ó\x00ý\x82{¹Õ\x96Èw\x9bæÄÛ<=Ûoï\x10n\x00\x00(\x00\x16\x00\x13\x00')
[30/Jun/2021 00:00:02] You're accessing the development server over HTTPS, but it only supports HTTP.

[30/Jun/2021 00:00:07] code 400, message Bad request version ('0.12\x00')
[30/Jun/2021 00:00:07] "   ¤ÿSMBr    @              @     PC NETWORK PROGRAM 1.0 MICROSOFT NETWORKS 1.03 MICROSOFT NETWORKS 3.0 LANMAN1.0 LM1.2X002 Samba NT LANMAN 1.0 NT LM 0.12 " 400 -
----------------------------------------
Exception happened during processing of request from ('204.93.180.13', 32943)
Traceback (most recent call last):
  File "/home/python/python3/lib/python3.8/socketserver.py", line 650, in process_request_thread
    self.finish_request(request, client_address)
  File "/home/python/python3/lib/python3.8/socketserver.py", line 360, in finish_request
    self.RequestHandlerClass(request, client_address, self)
  File "/home/python/python3/lib/python3.8/socketserver.py", line 720, in __init__
    self.handle()
  File "/home/python/python3/lib/python3.8/site-packages/django/core/servers/basehttp.py", line 169, in handle
    self.handle_one_request()
  File "/home/python/python3/lib/python3.8/site-packages/django/core/servers/basehttp.py", line 179, in handle_one_request
    self.raw_requestline = self.rfile.readline(65537)
  File "/home/python/python3/lib/python3.8/socket.py", line 669, in readinto
    return self._sock.recv_into(b)
ConnectionResetError: [Errno 104] Connection reset by peer
----------------------------------------
Invalid HTTP_HOST header: 'allen_cvm:8000'. The domain name provided is not valid according to RFC 1034/1035.
Bad Request: /
[30/Jun/2021 00:25:24] code 400, message Bad HTTP/0.9 request type ('l\x00')
[30/Jun/2021 00:25:24] "l          " 400 -
Invalid HTTP_HOST header: 'allen_cvm:8000'. The domain name provided is not valid according to RFC 1034/1035.
Bad Request: /nice ports,/Trinity.txt.bak
[30/Jun/2021 00:25:25] code 400, message Bad request syntax ('\x05\x04\x00\x01\x02\x80\x05\x01\x00\x03')
[30/Jun/2021 00:25:25] "  " 400 -
[30/Jun/2021 00:25:30] code 400, message Bad request syntax ('\x04\x01\x00\x16\x7f\x00\x00\x01root\x00')
[30/Jun/2021 00:25:30] "   root " 400 -
Invalid HTTP_HOST header: 'allen_cvm:8000'. The domain name provided is not valid according to RFC 1034/1035.
Bad Request: /
[30/Jun/2021 00:25:31] code 400, message Bad request version ('RTSP/1.0')
[30/Jun/2021 00:25:31] "OPTIONS / RTSP/1.0" 400 -
[30/Jun/2021 00:25:36] code 400, message Bad request version ('\x00\x01\x97|\x00\x00\x00\x00\x00\x00\x00\x00\x00\x00\x00\x00\x00\x00\x00\x00\x00\x00\x00\x00')
[30/Jun/2021 00:25:36] "  (rþ          |                    " 400 -
[30/Jun/2021 00:25:42] code 400, message Bad HTTP/0.9 request type ('\x00')
[30/Jun/2021 00:25:42] "          versionbind   " 400 -
[30/Jun/2021 00:25:47] code 400, message Bad HTTP/0.9 request type ('\x00')
[30/Jun/2021 00:25:47] "            " 400 -
[30/Jun/2021 00:25:47] code 400, message Bad request syntax ('HELP')
[30/Jun/2021 00:25:47] "HELP" 400 -
[30/Jun/2021 00:25:48] code 400, message Bad request syntax ('\x16\x03\x00\x00S\x01\x00\x00O\x03\x00?G×÷º,îê²`~ó\x00ý\x82{¹Õ\x96Èw\x9bæÄÛ<=Ûoï\x10n\x00\x00(\x00\x16\x00\x13\x00')
[30/Jun/2021 00:25:48] You're accessing the development server over HTTPS, but it only supports HTTP.

[30/Jun/2021 00:25:53] code 400, message Bad request version ('0.12\x00')
[30/Jun/2021 00:25:53] "   ¤ÿSMBr    @              @     PC NETWORK PROGRAM 1.0 MICROSOFT NETWORKS 1.03 MICROSOFT NETWORKS 3.0 LANMAN1.0 LM1.2X002 Samba NT LANMAN 1.0 NT LM 0.12 " 400 -
[30/Jun/2021 00:25:53] code 400, message Bad request syntax ('\x01default')
[30/Jun/2021 00:25:53] "default" 400 -
[30/Jun/2021 00:55:12] code 400, message Bad HTTP/0.9 request type ('Z¥\x01')
[30/Jun/2021 00:55:12] "Z¥     " 400 -
----------------------------------------
Exception happened during processing of request from ('204.93.154.210', 58185)
Traceback (most recent call last):
  File "/home/python/python3/lib/python3.8/socketserver.py", line 650, in process_request_thread
    self.finish_request(request, client_address)
  File "/home/python/python3/lib/python3.8/socketserver.py", line 360, in finish_request
    self.RequestHandlerClass(request, client_address, self)
  File "/home/python/python3/lib/python3.8/socketserver.py", line 720, in __init__
    self.handle()
  File "/home/python/python3/lib/python3.8/site-packages/django/core/servers/basehttp.py", line 169, in handle
    self.handle_one_request()
  File "/home/python/python3/lib/python3.8/site-packages/django/core/servers/basehttp.py", line 179, in handle_one_request
    self.raw_requestline = self.rfile.readline(65537)
  File "/home/python/python3/lib/python3.8/socket.py", line 669, in readinto
    return self._sock.recv_into(b)
ConnectionResetError: [Errno 104] Connection reset by peer
----------------------------------------
Invalid HTTP_HOST header: 'allen_cvm:8000'. The domain name provided is not valid according to RFC 1034/1035.
Bad Request: /
[30/Jun/2021 01:05:21] code 400, message Bad HTTP/0.9 request type ('l\x00')
[30/Jun/2021 01:05:21] "l          " 400 -
Invalid HTTP_HOST header: 'allen_cvm:8000'. The domain name provided is not valid according to RFC 1034/1035.
Bad Request: /nice ports,/Trinity.txt.bak
[30/Jun/2021 01:05:21] code 400, message Bad request syntax ('\x05\x04\x00\x01\x02\x80\x05\x01\x00\x03')
[30/Jun/2021 01:05:21] "  " 400 -
[30/Jun/2021 01:05:30] code 400, message Bad request syntax ('\x04\x01\x00\x16\x7f\x00\x00\x01root\x00')
[30/Jun/2021 01:05:30] "   root " 400 -
Invalid HTTP_HOST header: 'allen_cvm:8000'. The domain name provided is not valid according to RFC 1034/1035.
Bad Request: /
[30/Jun/2021 01:05:30] code 400, message Bad request version ('RTSP/1.0')
[30/Jun/2021 01:05:30] "OPTIONS / RTSP/1.0" 400 -
[30/Jun/2021 01:05:37] code 400, message Bad request version ('\x00\x01\x97|\x00\x00\x00\x00\x00\x00\x00\x00\x00\x00\x00\x00\x00\x00\x00\x00\x00\x00\x00\x00')
[30/Jun/2021 01:05:37] "  (rþ          |                    " 400 -
[30/Jun/2021 01:05:43] code 400, message Bad HTTP/0.9 request type ('\x00')
[30/Jun/2021 01:05:43] "          versionbind   " 400 -
[30/Jun/2021 01:05:48] code 400, message Bad HTTP/0.9 request type ('\x00')
[30/Jun/2021 01:05:48] "            " 400 -
[30/Jun/2021 01:05:48] code 400, message Bad request syntax ('HELP')
[30/Jun/2021 01:05:48] "HELP" 400 -
[30/Jun/2021 01:05:48] code 400, message Bad request syntax ('\x16\x03\x00\x00S\x01\x00\x00O\x03\x00?G×÷º,îê²`~ó\x00ý\x82{¹Õ\x96Èw\x9bæÄÛ<=Ûoï\x10n\x00\x00(\x00\x16\x00\x13\x00')
[30/Jun/2021 01:05:48] You're accessing the development server over HTTPS, but it only supports HTTP.

[30/Jun/2021 01:05:54] code 400, message Bad request version ('0.12\x00')
[30/Jun/2021 01:05:54] "   ¤ÿSMBr    @              @     PC NETWORK PROGRAM 1.0 MICROSOFT NETWORKS 1.03 MICROSOFT NETWORKS 3.0 LANMAN1.0 LM1.2X002 Samba NT LANMAN 1.0 NT LM 0.12 " 400 -
[30/Jun/2021 01:16:41] code 400, message Bad HTTP/0.9 request type ('\x03\x00\x00/*à\x00\x00\x00\x00\x00Cookie:')
[30/Jun/2021 01:16:41] "  /*à     Cookie: mstshash=Administr" 400 -
